Workbook

Sheet Instrucciones
B1: Herramienta de gestión y rentabilidad porcina
B2: Curso «Gestión y rentabilidad de granjas porcinas» · AgroAcademy. Importes en pesos dominicanos (RD$).
B4: Para qué sirve
B5: Registrar los gastos y las ventas de cada lote y obtener, sin hacer cuentas a mano, el costo por cerdo, el costo por kilo, la conversión alimenticia, la mortalidad, el resultado, el margen y el punto de equilibrio.
B7: Las seis hojas
B8: 1 · Instrucciones | C8: Esta hoja.
B9: 2 · Registro de gastos | C9: Cada gasto en una fila: fecha, lote, categoría, concepto, cantidad y costo unitario. El total se calcula solo.
B10: 3 · Registro de ingresos | C10: Cada venta en una fila: lote, comprador, cerdos, kilos, precio por kilo y costos de la venta (transporte, comisión). El ingreso neto se calcula solo.
B11: 4 · Control de lotes | C11: Un renglón por lote: fechas, cerdos que entraron, muertos, peso de entrada y kilos de alimento consumidos. Costos, ventas y resultado se traen solos de los registros de gastos e ingresos.
B12: 5 · Indicadores | C12: Mortalidad, peso de venta, kilos producidos, conversión, ganancia diaria, costo por cerdo, por kg vendido y por kg producido, resultado y margen de cada lote. A la derecha, la calculadora del punto de equilibrio.
B13: 6 · Resumen | C13: Ingresos, costos, resultado y margen de toda la granja; los costos por categoría, fijos y variables, y la comparación de los lotes.
B15: Cómo se usa
B16: 1 | C16: Primero, en «Control de lotes», escriba el código de cada lote (por ejemplo L-03). Ese código se elige luego en los registros de gastos e ingresos.
B17: 2 | C17: Anote cada gasto el mismo día en «Registro de gastos», con su lote. Los gastos generales (salario fijo, luz de toda la granja) repártalos entre los lotes con un criterio fijo, por ejemplo por número de cerdos.
B18: 3 | C18: Al vender, anote la venta en «Registro de ingresos» con el peso total de los cerdos vendidos.
B19: 4 | C19: Complete en «Control de lotes» los muertos, el peso de entrada y los kilos de alimento. Mire «Indicadores» y «Resumen».
B21: Colores
B22: Celdas blancas | C22: Se escriben. Tienen validación: no aceptan números negativos ni categorías que no estén en la lista.
B23: Celdas grises | C23: Se calculan solas y están protegidas para que no se borre una fórmula por accidente. La protección NO tiene contraseña: Revisar → Desproteger hoja, si quiere adaptarla.
B24: Celdas amarillas | C24: Son DATOS DE EJEMPLO (los lotes L-01 y L-02 del curso). No son precios del mercado. Bórrelos (seleccione las celdas y pulse Suprimir) y escriba los suyos.
B25: «falta dato» | C25: Aparece en rojo cuando falta un dato esencial para el cálculo. La herramienta no inventa un número en su lugar.
B27: Fórmulas que usa (las mismas del curso)
B28: Resultado | C28: Ingresos netos − costos totales
B29: Costo por cerdo | C29: Costo total del lote ÷ cerdos vendidos
B30: Costo por kg vendido | C30: Costo total ÷ kg vendidos
B31: Costo por kg producido | C31: (Costo total − compra de lechones) ÷ (kg vendidos − kg que entraron)
B32: Conversión alimenticia | C32: kg de alimento consumidos ÷ kg producidos
B33: Ganancia diaria | C33: (peso promedio de venta − peso de entrada) ÷ días en la granja
B34: Mortalidad | C34: Muertos ÷ cerdos que entraron
B35: Margen | C35: Resultado ÷ ingresos netos
B36: Punto de equilibrio | C36: Costos fijos ÷ (precio − costo variable por cerdo)
B38: Funciona en Excel 2010 o más nuevo, en Excel para teléfono y en Google Sheets (Archivo → Importar). Guarde una copia antes de borrar los ejemplos.

Sheet Registro de gastos
A1: Registro de gastos
A2: Una fila por gasto. El total se calcula solo. Elija el lote de la lista (los lotes se crean en la hoja «Control de lotes»).
A3: Blanco = se escribe · Gris = se calcula solo (protegido) · Amarillo = datos de EJEMPLO: bórrelos y escriba los suyos
A4: Fecha | B4: Lote | C4: Categoría | D4: Concepto | E4: Cantidad | F4: Unidad | G4: Costo unitario (RD$) | H4: Total (RD$) | I4: Fijo o variable
A5: 46027 | B5: L-01 | C5: Compra de lechones | D5: EJEMPLO · 50 lechones de 25 kg | E5: 50 | F5: lechón | G5: 4500 | H5: =IF(AND(E5="",G5=""),"",IF(OR(E5="",G5=""),"falta dato",E5*G5)) | I5: Variable
A6: 46132 | B6: L-01 | C6: Alimento | D6: EJEMPLO · alimento de todo el engorde | E6: 12500 | F6: kg | G6: 32 | H6: =IF(AND(E6="",G6=""),"",IF(OR(E6="",G6=""),"falta dato",E6*G6)) | I6: Variable
A7: 46132 | B7: L-01 | C7: Sanidad | D7: EJEMPLO · vacunas y medicamentos | E7: 1 | F7: global | G7: 18000 | H7: =IF(AND(E7="",G7=""),"",IF(OR(E7="",G7=""),"falta dato",E7*G7)) | I7: Variable
A8: 46132 | B8: L-01 | C8: Mano de obra | D8: EJEMPLO · parte del salario del encargado | E8: 1 | F8: global | G8: 45000 | H8: =IF(AND(E8="",G8=""),"",IF(OR(E8="",G8=""),"falta dato",E8*G8)) | I8: Fijo
A9: 46132 | B9: L-01 | C9: Agua y energía | D9: EJEMPLO · parte de la factura | E9: 1 | F9: global | G9: 12000 | H9: =IF(AND(E9="",G9=""),"",IF(OR(E9="",G9=""),"falta dato",E9*G9)) | I9: Fijo
A10: 46132 | B10: L-01 | C10: Otros | D10: EJEMPLO · mantenimiento y depreciación | E10: 1 | F10: global | G10: 20000 | H10: =IF(AND(E10="",G10=""),"",IF(OR(E10="",G10=""),"falta dato",E10*G10)) | I10: Fijo
A11: 46054 | B11: L-02 | C11: Compra de lechones | D11: EJEMPLO · 20 lechones propios a valor de mercado | E11: 20 | F11: lechón | G11: 3800 | H11: =IF(AND(E11="",G11=""),"",IF(OR(E11="",G11=""),"falta dato",E11*G11)) | I11: Variable
A12: 46157 | B12: L-02 | C12: Alimento | D12: EJEMPLO · alimento de todo el engorde | E12: 5000 | F12: kg | G12: 32 | H12: =IF(AND(E12="",G12=""),"",IF(OR(E12="",G12=""),"falta dato",E12*G12)) | I12: Variable
A13: 46157 | B13: L-02 | C13: Sanidad | D13: EJEMPLO · vacunas y medicamentos | E13: 1 | F13: global | G13: 6000 | H13: =IF(AND(E13="",G13=""),"",IF(OR(E13="",G13=""),"falta dato",E13*G13)) | I13: Variable
A14: 46157 | B14: L-02 | C14: Mano de obra | D14: EJEMPLO · parte del salario | E14: 1 | F14: global | G14: 18000 | H14: =IF(AND(E14="",G14=""),"",IF(OR(E14="",G14=""),"falta dato",E14*G14)) | I14: Fijo
A15: 46157 | B15: L-02 | C15: Agua y energía | D15: EJEMPLO · parte de la factura | E15: 1 | F15: global | G15: 5000 | H15: =IF(AND(E15="",G15=""),"",IF(OR(E15="",G15=""),"falta dato",E15*G15)) | I15: Fijo
A16: 46157 | B16: L-02 | C16: Otros | D16: EJEMPLO · mantenimiento y depreciación | E16: 1 | F16: global | G16: 7000 | H16: =IF(AND(E16="",G16=""),"",IF(OR(E16="",G16=""),"falta dato",E16*G16)) | I16: Fijo
H17: =IF(AND(E17="",G17=""),"",IF(OR(E17="",G17=""),"falta dato",E17*G17))
H18: =IF(AND(E18="",G18=""),"",IF(OR(E18="",G18=""),"falta dato",E18*G18))
H19: =IF(AND(E19="",G19=""),"",IF(OR(E19="",G19=""),"falta dato",E19*G19))
H20: =IF(AND(E20="",G20=""),"",IF(OR(E20="",G20=""),"falta dato",E20*G20))
H21: =IF(AND(E21="",G21=""),"",IF(OR(E21="",G21=""),"falta dato",E21*G21))
H22: =IF(AND(E22="",G22=""),"",IF(OR(E22="",G22=""),"falta dato",E22*G22))
H23: =IF(AND(E23="",G23=""),"",IF(OR(E23="",G23=""),"falta dato",E23*G23))
H24: =IF(AND(E24="",G24=""),"",IF(OR(E24="",G24=""),"falta dato",E24*G24))
H25: =IF(AND(E25="",G25=""),"",IF(OR(E25="",G25=""),"falta dato",E25*G25))
H26: =IF(AND(E26="",G26=""),"",IF(OR(E26="",G26=""),"falta dato",E26*G26))
H27: =IF(AND(E27="",G27=""),"",IF(OR(E27="",G27=""),"falta dato",E27*G27))
H28: =IF(AND(E28="",G28=""),"",IF(OR(E28="",G28=""),"falta dato",E28*G28))
... H505: =IF(AND(E505="",G505=""),"",IF(OR(E505="",G505=""),"falta dato",E505*G505))

Sheet Registro de ingresos
A1: Registro de ingresos
A2: Una fila por venta. Costos de venta = transporte, comisión y otros descuentos que salen del precio.
A3: Blanco = se escribe · Gris = se calcula solo (protegido) · Amarillo = datos de EJEMPLO: bórrelos y escriba los suyos
A4: Fecha | B4: Lote | C4: Comprador | D4: Cerdos vendidos | E4: Peso total vendido (kg) | F4: Precio por kg (RD$) | G4: Ingreso bruto (RD$) | H4: Costos de venta (RD$) | I4: Ingreso neto (RD$)
A5: 46137 | B5: L-01 | C5: EJEMPLO · Comprador A | D5: 48 | E5: 5040 | F5: 150 | G5: =IF(AND(E5="",F5=""),"",IF(OR(E5="",F5=""),"falta dato",E5*F5)) | H5: 14400 | I5: =IF(G5="","",IF(ISNUMBER(G5),G5-IF(H5="",0,H5),"falta dato"))
A6: 46164 | B6: L-02 | C6: EJEMPLO · Intermediario (2 % + transporte) | D6: 19 | E6: 1900 | F6: 150 | G6: =IF(AND(E6="",F6=""),"",IF(OR(E6="",F6=""),"falta dato",E6*F6)) | H6: 11400 | I6: =IF(G6="","",IF(ISNUMBER(G6),G6-IF(H6="",0,H6),"falta dato"))
G7: =IF(AND(E7="",F7=""),"",IF(OR(E7="",F7=""),"falta dato",E7*F7)) | I7: =IF(G7="","",IF(ISNUMBER(G7),G7-IF(H7="",0,H7),"falta dato"))
G8: =IF(AND(E8="",F8=""),"",IF(OR(E8="",F8=""),"falta dato",E8*F8)) | I8: =IF(G8="","",IF(ISNUMBER(G8),G8-IF(H8="",0,H8),"falta dato"))
G9: =IF(AND(E9="",F9=""),"",IF(OR(E9="",F9=""),"falta dato",E9*F9)) | I9: =IF(G9="","",IF(ISNUMBER(G9),G9-IF(H9="",0,H9),"falta dato"))
G10: =IF(AND(E10="",F10=""),"",IF(OR(E10="",F10=""),"falta dato",E10*F10)) | I10: =IF(G10="","",IF(ISNUMBER(G10),G10-IF(H10="",0,H10),"falta dato"))
G11: =IF(AND(E11="",F11=""),"",IF(OR(E11="",F11=""),"falta dato",E11*F11)) | I11: =IF(G11="","",IF(ISNUMBER(G11),G11-IF(H11="",0,H11),"falta dato"))
G12: =IF(AND(E12="",F12=""),"",IF(OR(E12="",F12=""),"falta dato",E12*F12)) | I12: =IF(G12="","",IF(ISNUMBER(G12),G12-IF(H12="",0,H12),"falta dato"))
G13: =IF(AND(E13="",F13=""),"",IF(OR(E13="",F13=""),"falta dato",E13*F13)) | I13: =IF(G13="","",IF(ISNUMBER(G13),G13-IF(H13="",0,H13),"falta dato"))
G14: =IF(AND(E14="",F14=""),"",IF(OR(E14="",F14=""),"falta dato",E14*F14)) | I14: =IF(G14="","",IF(ISNUMBER(G14),G14-IF(H14="",0,H14),"falta dato"))
G15: =IF(AND(E15="",F15=""),"",IF(OR(E15="",F15=""),"falta dato",E15*F15)) | I15: =IF(G15="","",IF(ISNUMBER(G15),G15-IF(H15="",0,H15),"falta dato"))
G16: =IF(AND(E16="",F16=""),"",IF(OR(E16="",F16=""),"falta dato",E16*F16)) | I16: =IF(G16="","",IF(ISNUMBER(G16),G16-IF(H16="",0,H16),"falta dato"))
G17: =IF(AND(E17="",F17=""),"",IF(OR(E17="",F17=""),"falta dato",E17*F17)) | I17: =IF(G17="","",IF(ISNUMBER(G17),G17-IF(H17="",0,H17),"falta dato"))
G18: =IF(AND(E18="",F18=""),"",IF(OR(E18="",F18=""),"falta dato",E18*F18)) | I18: =IF(G18="","",IF(ISNUMBER(G18),G18-IF(H18="",0,H18),"falta dato"))
... G505: =IF(AND(E505="",F505=""),"",IF(OR(E505="",F505=""),"falta dato",E505*F505)) | I505: =IF(G505="","",IF(ISNUMBER(G505),G505-IF(H505="",0,H505),"falta dato"))

Sheet Control de lotes
A1: Control de lotes
A2: Un renglón por lote. Escriba las columnas blancas; las grises se traen de los registros de gastos e ingresos.
A3: Blanco = se escribe · Gris = se calcula solo (protegido) · Amarillo = datos de EJEMPLO: bórrelos y escriba los suyos
A4: Lote | B4: Fecha de entrada | C4: Fecha de venta | D4: Cerdos que entraron | E4: Muertos | F4: Peso promedio de entrada (kg) | G4: Alimento consumido (kg) | H4: Cerdos vendidos | I4: Días en la granja | J4: kg vendidos | K4: Costo total (RD$) | L4: Compra de lechones (RD$) | M4: Ingreso neto (RD$) | N4: Resultado (RD$)
A5: L-01 | B5: 46027 | C5: 46137 | D5: 50 | E5: 2 | F5: 25 | G5: 12500 | H5: =IF(A5="","",IF(D5="","falta dato",D5-IF(E5="",0,E5))) | I5: =IF(A5="","",IF(OR(B5="",C5=""),"falta dato",C5-B5)) | J5: =IF(A5="","",SUMIF('Registro de ingresos'!$B$5:$B$505,A5,'Registro de ingresos'!$E$5:$E$505)) | K5: =IF(A5="","",SUMIF('Registro de gastos'!$B$5:$B$505,A5,'Registro de gastos'!$H$5:$H$505)) | L5: =IF(A5="","",SUMIFS('Registro de gastos'!$H$5:$H$505,'Registro de gastos'!$B$5:$B$505,A5,'Registro de gastos'!$C$5:$C$505,"Compra de lechones")) | M5: =IF(A5="","",SUMIF('Registro de ingresos'!$B$5:$B$505,A5,'Registro de ingresos'!$I$5:$I$505)) | N5: =IF(A5="","",IF(M5=0,"sin ventas todavía",M5-K5))
A6: L-02 | B6: 46054 | C6: 46164 | D6: 20 | E6: 1 | F6: 25 | G6: 5000 | H6: =IF(A6="","",IF(D6="","falta dato",D6-IF(E6="",0,E6))) | I6: =IF(A6="","",IF(OR(B6="",C6=""),"falta dato",C6-B6)) | J6: =IF(A6="","",SUMIF('Registro de ingresos'!$B$5:$B$505,A6,'Registro de ingresos'!$E$5:$E$505)) | K6: =IF(A6="","",SUMIF('Registro de gastos'!$B$5:$B$505,A6,'Registro de gastos'!$H$5:$H$505)) | L6: =IF(A6="","",SUMIFS('Registro de gastos'!$H$5:$H$505,'Registro de gastos'!$B$5:$B$505,A6,'Registro de gastos'!$C$5:$C$505,"Compra de lechones")) | M6: =IF(A6="","",SUMIF('Registro de ingresos'!$B$5:$B$505,A6,'Registro de ingresos'!$I$5:$I$505)) | N6: =IF(A6="","",IF(M6=0,"sin ventas todavía",M6-K6))
H7: =IF(A7="","",IF(D7="","falta dato",D7-IF(E7="",0,E7))) | I7: =IF(A7="","",IF(OR(B7="",C7=""),"falta dato",C7-B7)) | J7: =IF(A7="","",SUMIF('Registro de ingresos'!$B$5:$B$505,A7,'Registro de ingresos'!$E$5:$E$505)) | K7: =IF(A7="","",SUMIF('Registro de gastos'!$B$5:$B$505,A7,'Registro de gastos'!$H$5:$H$505)) | L7: =IF(A7="","",SUMIFS('Registro de gastos'!$H$5:$H$505,'Registro de gastos'!$B$5:$B$505,A7,'Registro de gastos'!$C$5:$C$505,"Compra de lechones")) | M7: =IF(A7="","",SUMIF('Registro de ingresos'!$B$5:$B$505,A7,'Registro de ingresos'!$I$5:$I$505)) | N7: =IF(A7="","",IF(M7=0,"sin ventas todavía",M7-K7))
H8: =IF(A8="","",IF(D8="","falta dato",D8-IF(E8="",0,E8))) | I8: =IF(A8="","",IF(OR(B8="",C8=""),"falta dato",C8-B8)) | J8: =IF(A8="","",SUMIF('Registro de ingresos'!$B$5:$B$505,A8,'Registro de ingresos'!$E$5:$E$505)) | K8: =IF(A8="","",SUMIF('Registro de gastos'!$B$5:$B$505,A8,'Registro de gastos'!$H$5:$H$505)) | L8: =IF(A8="","",SUMIFS('Registro de gastos'!$H$5:$H$505,'Registro de gastos'!$B$5:$B$505,A8,'Registro de gastos'!$C$5:$C$505,"Compra de lechones")) | M8: =IF(A8="","",SUMIF('Registro de ingresos'!$B$5:$B$505,A8,'Registro de ingresos'!$I$5:$I$505)) | N8: =IF(A8="","",IF(M8=0,"sin ventas todavía",M8-K8))
H9: =IF(A9="","",IF(D9="","falta dato",D9-IF(E9="",0,E9))) | I9: =IF(A9="","",IF(OR(B9="",C9=""),"falta dato",C9-B9)) | J9: =IF(A9="","",SUMIF('Registro de ingresos'!$B$5:$B$505,A9,'Registro de ingresos'!$E$5:$E$505)) | K9: =IF(A9="","",SUMIF('Registro de gastos'!$B$5:$B$505,A9,'Registro de gastos'!$H$5:$H$505)) | L9: =IF(A9="","",SUMIFS('Registro de gastos'!$H$5:$H$505,'Registro de gastos'!$B$5:$B$505,A9,'Registro de gastos'!$C$5:$C$505,"Compra de lechones")) | M9: =IF(A9="","",SUMIF('Registro de ingresos'!$B$5:$B$505,A9,'Registro de ingresos'!$I$5:$I$505)) | N9: =IF(A9="","",IF(M9=0,"sin ventas todavía",M9-K9))
H10: =IF(A10="","",IF(D10="","falta dato",D10-IF(E10="",0,E10))) | I10: =IF(A10="","",IF(OR(B10="",C10=""),"falta dato",C10-B10)) | J10: =IF(A10="","",SUMIF('Registro de ingresos'!$B$5:$B$505,A10,'Registro de ingresos'!$E$5:$E$505)) | K10: =IF(A10="","",SUMIF('Registro de gastos'!$B$5:$B$505,A10,'Registro de gastos'!$H$5:$H$505)) | L10: =IF(A10="","",SUMIFS('Registro de gastos'!$H$5:$H$505,'Registro de gastos'!$B$5:$B$505,A10,'Registro de gastos'!$C$5:$C$505,"Compra de lechones")) | M10: =IF(A10="","",SUMIF('Registro de ingresos'!$B$5:$B$505,A10,'Registro de ingresos'!$I$5:$I$505)) | N10: =IF(A10="","",IF(M10=0,"sin ventas todavía",M10-K10))
H11: =IF(A11="","",IF(D11="","falta dato",D11-IF(E11="",0,E11))) | I11: =IF(A11="","",IF(OR(B11="",C11=""),"falta dato",C11-B11)) | J11: =IF(A11="","",SUMIF('Registro de ingresos'!$B$5:$B$505,A11,'Registro de ingresos'!$E$5:$E$505)) | K11: =IF(A11="","",SUMIF('Registro de gastos'!$B$5:$B$505,A11,'Registro de gastos'!$H$5:$H$505)) | L11: =IF(A11="","",SUMIFS('Registro de gastos'!$H$5:$H$505,'Registro de gastos'!$B$5:$B$505,A11,'Registro de gastos'!$C$5:$C$505,"Compra de lechones")) | M11: =IF(A11="","",SUMIF('Registro de ingresos'!$B$5:$B$505,A11,'Registro de ingresos'!$I$5:$I$505)) | N11: =IF(A11="","",IF(M11=0,"sin ventas todavía",M11-K11))
H12: =IF(A12="","",IF(D12="","falta dato",D12-IF(E12="",0,E12))) | I12: =IF(A12="","",IF(OR(B12="",C12=""),"falta dato",C12-B12)) | J12: =IF(A12="","",SUMIF('Registro de ingresos'!$B$5:$B$505,A12,'Registro de ingresos'!$E$5:$E$505)) | K12: =IF(A12="","",SUMIF('Registro de gastos'!$B$5:$B$505,A12,'Registro de gastos'!$H$5:$H$505)) | L12: =IF(A12="","",SUMIFS('Registro de gastos'!$H$5:$H$505,'Registro de gastos'!$B$5:$B$505,A12,'Registro de gastos'!$C$5:$C$505,"Compra de lechones")) | M12: =IF(A12="","",SUMIF('Registro de ingresos'!$B$5:$B$505,A12,'Registro de ingresos'!$I$5:$I$505)) | N12: =IF(A12="","",IF(M12=0,"sin ventas todavía",M12-K12))
H13: =IF(A13="","",IF(D13="","falta dato",D13-IF(E13="",0,E13))) | I13: =IF(A13="","",IF(OR(B13="",C13=""),"falta dato",C13-B13)) | J13: =IF(A13="","",SUMIF('Registro de ingresos'!$B$5:$B$505,A13,'Registro de ingresos'!$E$5:$E$505)) | K13: =IF(A13="","",SUMIF('Registro de gastos'!$B$5:$B$505,A13,'Registro de gastos'!$H$5:$H$505)) | L13: =IF(A13="","",SUMIFS('Registro de gastos'!$H$5:$H$505,'Registro de gastos'!$B$5:$B$505,A13,'Registro de gastos'!$C$5:$C$505,"Compra de lechones")) | M13: =IF(A13="","",SUMIF('Registro de ingresos'!$B$5:$B$505,A13,'Registro de ingresos'!$I$5:$I$505)) | N13: =IF(A13="","",IF(M13=0,"sin ventas todavía",M13-K13))
H14: =IF(A14="","",IF(D14="","falta dato",D14-IF(E14="",0,E14))) | I14: =IF(A14="","",IF(OR(B14="",C14=""),"falta dato",C14-B14)) | J14: =IF(A14="","",SUMIF('Registro de ingresos'!$B$5:$B$505,A14,'Registro de ingresos'!$E$5:$E$505)) | K14: =IF(A14="","",SUMIF('Registro de gastos'!$B$5:$B$505,A14,'Registro de gastos'!$H$5:$H$505)) | L14: =IF(A14="","",SUMIFS('Registro de gastos'!$H$5:$H$505,'Registro de gastos'!$B$5:$B$505,A14,'Registro de gastos'!$C$5:$C$505,"Compra de lechones")) | M14: =IF(A14="","",SUMIF('Registro de ingresos'!$B$5:$B$505,A14,'Registro de ingresos'!$I$5:$I$505)) | N14: =IF(A14="","",IF(M14=0,"sin ventas todavía",M14-K14))
H15: =IF(A15="","",IF(D15="","falta dato",D15-IF(E15="",0,E15))) | I15: =IF(A15="","",IF(OR(B15="",C15=""),"falta dato",C15-B15)) | J15: =IF(A15="","",SUMIF('Registro de ingresos'!$B$5:$B$505,A15,'Registro de ingresos'!$E$5:$E$505)) | K15: =IF(A15="","",SUMIF('Registro de gastos'!$B$5:$B$505,A15,'Registro de gastos'!$H$5:$H$505)) | L15: =IF(A15="","",SUMIFS('Registro de gastos'!$H$5:$H$505,'Registro de gastos'!$B$5:$B$505,A15,'Registro de gastos'!$C$5:$C$505,"Compra de lechones")) | M15: =IF(A15="","",SUMIF('Registro de ingresos'!$B$5:$B$505,A15,'Registro de ingresos'!$I$5:$I$505)) | N15: =IF(A15="","",IF(M15=0,"sin ventas todavía",M15-K15))
H16: =IF(A16="","",IF(D16="","falta dato",D16-IF(E16="",0,E16))) | I16: =IF(A16="","",IF(OR(B16="",C16=""),"falta dato",C16-B16)) | J16: =IF(A16="","",SUMIF('Registro de ingresos'!$B$5:$B$505,A16,'Registro de ingresos'!$E$5:$E$505)) | K16: =IF(A16="","",SUMIF('Registro de gastos'!$B$5:$B$505,A16,'Registro de gastos'!$H$5:$H$505)) | L16: =IF(A16="","",SUMIFS('Registro de gastos'!$H$5:$H$505,'Registro de gastos'!$B$5:$B$505,A16,'Registro de gastos'!$C$5:$C$505,"Compra de lechones")) | M16: =IF(A16="","",SUMIF('Registro de ingresos'!$B$5:$B$505,A16,'Registro de ingresos'!$I$5:$I$505)) | N16: =IF(A16="","",IF(M16=0,"sin ventas todavía",M16-K16))
H17: =IF(A17="","",IF(D17="","falta dato",D17-IF(E17="",0,E17))) | I17: =IF(A17="","",IF(OR(B17="",C17=""),"falta dato",C17-B17)) | J17: =IF(A17="","",SUMIF('Registro de ingresos'!$B$5:$B$505,A17,'Registro de ingresos'!$E$5:$E$505)) | K17: =IF(A17="","",SUMIF('Registro de gastos'!$B$5:$B$505,A17,'Registro de gastos'!$H$5:$H$505)) | L17: =IF(A17="","",SUMIFS('Registro de gastos'!$H$5:$H$505,'Registro de gastos'!$B$5:$B$505,A17,'Registro de gastos'!$C$5:$C$505,"Compra de lechones")) | M17: =IF(A17="","",SUMIF('Registro de ingresos'!$B$5:$B$505,A17,'Registro de ingresos'!$I$5:$I$505)) | N17: =IF(A17="","",IF(M17=0,"sin ventas todavía",M17-K17))
H18: =IF(A18="","",IF(D18="","falta dato",D18-IF(E18="",0,E18))) | I18: =IF(A18="","",IF(OR(B18="",C18=""),"falta dato",C18-B18)) | J18: =IF(A18="","",SUMIF('Registro de ingresos'!$B$5:$B$505,A18,'Registro de ingresos'!$E$5:$E$505)) | K18: =IF(A18="","",SUMIF('Registro de gastos'!$B$5:$B$505,A18,'Registro de gastos'!$H$5:$H$505)) | L18: =IF(A18="","",SUMIFS('Registro de gastos'!$H$5:$H$505,'Registro de gastos'!$B$5:$B$505,A18,'Registro de gastos'!$C$5:$C$505,"Compra de lechones")) | M18: =IF(A18="","",SUMIF('Registro de ingresos'!$B$5:$B$505,A18,'Registro de ingresos'!$I$5:$I$505)) | N18: =IF(A18="","",IF(M18=0,"sin ventas todavía",M18-K18))
... H54: =IF(A54="","",IF(D54="","falta dato",D54-IF(E54="",0,E54))) | I54: =IF(A54="","",IF(OR(B54="",C54=""),"falta dato",C54-B54)) | J54: =IF(A54="","",SUMIF('Registro de ingresos'!$B$5:$B$505,A54,'Registro de ingresos'!$E$5:$E$505)) | K54: =IF(A54="","",SUMIF('Registro de gastos'!$B$5:$B$505,A54,'Registro de gastos'!$H$5:$H$505)) | L54: =IF(A54="","",SUMIFS('Registro de gastos'!$H$5:$H$505,'Registro de gastos'!$B$5:$B$505,A54,'Registro de gastos'!$C$5:$C$505,"Compra de lechones")) | M54: =IF(A54="","",SUMIF('Registro de ingresos'!$B$5:$B$505,A54,'Registro de ingresos'!$I$5:$I$505)) | N54: =IF(A54="","",IF(M54=0,"sin ventas todavía",M54-K54))

Sheet Indicadores
A1: Indicadores por lote
A2: Todo se calcula solo con los datos de «Control de lotes», «Registro de gastos» y «Registro de ingresos». A la derecha: punto de equilibrio del mes.
A3: Blanco = se escribe · Gris = se calcula solo (protegido) · Amarillo = datos de EJEMPLO: bórrelos y escriba los suyos
A4: Lote | B4: Mortalidad | C4: Peso promedio de venta (kg) | D4: kg producidos | E4: Conversión alimenticia | F4: Ganancia diaria (kg/día) | G4: Costo por cerdo (RD$) | H4: Costo por kg vendido (RD$) | I4: Costo por kg producido (RD$) | J4: Resultado (RD$) | K4: Margen | N4: Punto de equilibrio del mes
A5: =IF('Control de lotes'!A5="","",'Control de lotes'!A5) | B5: =IF(A5="","",IF(OR('Control de lotes'!D5="",'Control de lotes'!D5=0),"falta dato",IF('Control de lotes'!E5="",0,'Control de lotes'!E5)/'Control de lotes'!D5)) | C5: =IF(A5="","",IF(OR(NOT(ISNUMBER('Control de lotes'!H5)),'Control de lotes'!J5=0),"falta dato",IF('Control de lotes'!H5<=0,"falta dato",'Control de lotes'!J5/'Control de lotes'!H5))) | D5: =IF(A5="","",IF(OR('Control de lotes'!J5=0,'Control de lotes'!D5="",'Control de lotes'!F5=""),"falta dato",'Control de lotes'!J5-'Control de lotes'!D5*'Control de lotes'!F5)) | E5: =IF(A5="","",IF(OR('Control de lotes'!G5="",NOT(ISNUMBER(D5))),"falta dato",IF(D5<=0,"falta dato",'Control de lotes'!G5/D5))) | F5: =IF(A5="","",IF(OR(NOT(ISNUMBER(C5)),'Control de lotes'!F5="",NOT(ISNUMBER('Control de lotes'!I5))),"falta dato",IF('Control de lotes'!I5<=0,"falta dato",(C5-'Control de lotes'!F5)/'Control de lotes'!I5))) | G5: =IF(A5="","",IF(OR(NOT(ISNUMBER('Control de lotes'!H5)),'Control de lotes'!K5=0),"falta dato",IF('Control de lotes'!H5<=0,"falta dato",'Control de lotes'!K5/'Control de lotes'!H5))) | H5: =IF(A5="","",IF(OR('Control de lotes'!J5=0,'Control de lotes'!K5=0),"falta dato",'Control de lotes'!K5/'Control de lotes'!J5)) | I5: =IF(A5="","",IF(OR(NOT(ISNUMBER(D5)),'Control de lotes'!K5=0),"falta dato",IF(D5<=0,"falta dato",('Control de lotes'!K5-'Control de lotes'!L5)/D5))) | J5: =IF(A5="","",'Control de lotes'!N5) | K5: =IF(A5="","",IF(NOT(ISNUMBER('Control de lotes'!N5)),"falta dato",IF('Control de lotes'!M5<=0,"falta dato",'Control de lotes'!N5/'Control de lotes'!M5))) | N5: Costos fijos del mes | O5: 90000
A6: =IF('Control de lotes'!A6="","",'Control de lotes'!A6) | B6: =IF(A6="","",IF(OR('Control de lotes'!D6="",'Control de lotes'!D6=0),"falta dato",IF('Control de lotes'!E6="",0,'Control de lotes'!E6)/'Control de lotes'!D6)) | C6: =IF(A6="","",IF(OR(NOT(ISNUMBER('Control de lotes'!H6)),'Control de lotes'!J6=0),"falta dato",IF('Control de lotes'!H6<=0,"falta dato",'Control de lotes'!J6/'Control de lotes'!H6))) | D6: =IF(A6="","",IF(OR('Control de lotes'!J6=0,'Control de lotes'!D6="",'Control de lotes'!F6=""),"falta dato",'Control de lotes'!J6-'Control de lotes'!D6*'Control de lotes'!F6)) | E6: =IF(A6="","",IF(OR('Control de lotes'!G6="",NOT(ISNUMBER(D6))),"falta dato",IF(D6<=0,"falta dato",'Control de lotes'!G6/D6))) | F6: =IF(A6="","",IF(OR(NOT(ISNUMBER(C6)),'Control de lotes'!F6="",NOT(ISNUMBER('Control de lotes'!I6))),"falta dato",IF('Control de lotes'!I6<=0,"falta dato",(C6-'Control de lotes'!F6)/'Control de lotes'!I6))) | G6: =IF(A6="","",IF(OR(NOT(ISNUMBER('Control de lotes'!H6)),'Control de lotes'!K6=0),"falta dato",IF('Control de lotes'!H6<=0,"falta dato",'Control de lotes'!K6/'Control de lotes'!H6))) | H6: =IF(A6="","",IF(OR('Control de lotes'!J6=0,'Control de lotes'!K6=0),"falta dato",'Control de lotes'!K6/'Control de lotes'!J6)) | I6: =IF(A6="","",IF(OR(NOT(ISNUMBER(D6)),'Control de lotes'!K6=0),"falta dato",IF(D6<=0,"falta dato",('Control de lotes'!K6-'Control de lotes'!L6)/D6))) | J6: =IF(A6="","",'Control de lotes'!N6) | K6: =IF(A6="","",IF(NOT(ISNUMBER('Control de lotes'!N6)),"falta dato",IF('Control de lotes'!M6<=0,"falta dato",'Control de lotes'!N6/'Control de lotes'!M6))) | N6: Precio de venta por cerdo | O6: 17500
A7: =IF('Control de lotes'!A7="","",'Control de lotes'!A7) | B7: =IF(A7="","",IF(OR('Control de lotes'!D7="",'Control de lotes'!D7=0),"falta dato",IF('Control de lotes'!E7="",0,'Control de lotes'!E7)/'Control de lotes'!D7)) | C7: =IF(A7="","",IF(OR(NOT(ISNUMBER('Control de lotes'!H7)),'Control de lotes'!J7=0),"falta dato",IF('Control de lotes'!H7<=0,"falta dato",'Control de lotes'!J7/'Control de lotes'!H7))) | D7: =IF(A7="","",IF(OR('Control de lotes'!J7=0,'Control de lotes'!D7="",'Control de lotes'!F7=""),"falta dato",'Control de lotes'!J7-'Control de lotes'!D7*'Control de lotes'!F7)) | E7: =IF(A7="","",IF(OR('Control de lotes'!G7="",NOT(ISNUMBER(D7))),"falta dato",IF(D7<=0,"falta dato",'Control de lotes'!G7/D7))) | F7: =IF(A7="","",IF(OR(NOT(ISNUMBER(C7)),'Control de lotes'!F7="",NOT(ISNUMBER('Control de lotes'!I7))),"falta dato",IF('Control de lotes'!I7<=0,"falta dato",(C7-'Control de lotes'!F7)/'Control de lotes'!I7))) | G7: =IF(A7="","",IF(OR(NOT(ISNUMBER('Control de lotes'!H7)),'Control de lotes'!K7=0),"falta dato",IF('Control de lotes'!H7<=0,"falta dato",'Control de lotes'!K7/'Control de lotes'!H7))) | H7: =IF(A7="","",IF(OR('Control de lotes'!J7=0,'Control de lotes'!K7=0),"falta dato",'Control de lotes'!K7/'Control de lotes'!J7)) | I7: =IF(A7="","",IF(OR(NOT(ISNUMBER(D7)),'Control de lotes'!K7=0),"falta dato",IF(D7<=0,"falta dato",('Control de lotes'!K7-'Control de lotes'!L7)/D7))) | J7: =IF(A7="","",'Control de lotes'!N7) | K7: =IF(A7="","",IF(NOT(ISNUMBER('Control de lotes'!N7)),"falta dato",IF('Control de lotes'!M7<=0,"falta dato",'Control de lotes'!N7/'Control de lotes'!M7))) | N7: Costo variable por cerdo | O7: 13000
A8: =IF('Control de lotes'!A8="","",'Control de lotes'!A8) | B8: =IF(A8="","",IF(OR('Control de lotes'!D8="",'Control de lotes'!D8=0),"falta dato",IF('Control de lotes'!E8="",0,'Control de lotes'!E8)/'Control de lotes'!D8)) | C8: =IF(A8="","",IF(OR(NOT(ISNUMBER('Control de lotes'!H8)),'Control de lotes'!J8=0),"falta dato",IF('Control de lotes'!H8<=0,"falta dato",'Control de lotes'!J8/'Control de lotes'!H8))) | D8: =IF(A8="","",IF(OR('Control de lotes'!J8=0,'Control de lotes'!D8="",'Control de lotes'!F8=""),"falta dato",'Control de lotes'!J8-'Control de lotes'!D8*'Control de lotes'!F8)) | E8: =IF(A8="","",IF(OR('Control de lotes'!G8="",NOT(ISNUMBER(D8))),"falta dato",IF(D8<=0,"falta dato",'Control de lotes'!G8/D8))) | F8: =IF(A8="","",IF(OR(NOT(ISNUMBER(C8)),'Control de lotes'!F8="",NOT(ISNUMBER('Control de lotes'!I8))),"falta dato",IF('Control de lotes'!I8<=0,"falta dato",(C8-'Control de lotes'!F8)/'Control de lotes'!I8))) | G8: =IF(A8="","",IF(OR(NOT(ISNUMBER('Control de lotes'!H8)),'Control de lotes'!K8=0),"falta dato",IF('Control de lotes'!H8<=0,"falta dato",'Control de lotes'!K8/'Control de lotes'!H8))) | H8: =IF(A8="","",IF(OR('Control de lotes'!J8=0,'Control de lotes'!K8=0),"falta dato",'Control de lotes'!K8/'Control de lotes'!J8)) | I8: =IF(A8="","",IF(OR(NOT(ISNUMBER(D8)),'Control de lotes'!K8=0),"falta dato",IF(D8<=0,"falta dato",('Control de lotes'!K8-'Control de lotes'!L8)/D8))) | J8: =IF(A8="","",'Control de lotes'!N8) | K8: =IF(A8="","",IF(NOT(ISNUMBER('Control de lotes'!N8)),"falta dato",IF('Control de lotes'!M8<=0,"falta dato",'Control de lotes'!N8/'Control de lotes'!M8))) | N8: Margen de contribución por cerdo | O8: =IF(OR(O6="",O7=""),"falta dato",O6-O7)
A9: =IF('Control de lotes'!A9="","",'Control de lotes'!A9) | B9: =IF(A9="","",IF(OR('Control de lotes'!D9="",'Control de lotes'!D9=0),"falta dato",IF('Control de lotes'!E9="",0,'Control de lotes'!E9)/'Control de lotes'!D9)) | C9: =IF(A9="","",IF(OR(NOT(ISNUMBER('Control de lotes'!H9)),'Control de lotes'!J9=0),"falta dato",IF('Control de lotes'!H9<=0,"falta dato",'Control de lotes'!J9/'Control de lotes'!H9))) | D9: =IF(A9="","",IF(OR('Control de lotes'!J9=0,'Control de lotes'!D9="",'Control de lotes'!F9=""),"falta dato",'Control de lotes'!J9-'Control de lotes'!D9*'Control de lotes'!F9)) | E9: =IF(A9="","",IF(OR('Control de lotes'!G9="",NOT(ISNUMBER(D9))),"falta dato",IF(D9<=0,"falta dato",'Control de lotes'!G9/D9))) | F9: =IF(A9="","",IF(OR(NOT(ISNUMBER(C9)),'Control de lotes'!F9="",NOT(ISNUMBER('Control de lotes'!I9))),"falta dato",IF('Control de lotes'!I9<=0,"falta dato",(C9-'Control de lotes'!F9)/'Control de lotes'!I9))) | G9: =IF(A9="","",IF(OR(NOT(ISNUMBER('Control de lotes'!H9)),'Control de lotes'!K9=0),"falta dato",IF('Control de lotes'!H9<=0,"falta dato",'Control de lotes'!K9/'Control de lotes'!H9))) | H9: =IF(A9="","",IF(OR('Control de lotes'!J9=0,'Control de lotes'!K9=0),"falta dato",'Control de lotes'!K9/'Control de lotes'!J9)) | I9: =IF(A9="","",IF(OR(NOT(ISNUMBER(D9)),'Control de lotes'!K9=0),"falta dato",IF(D9<=0,"falta dato",('Control de lotes'!K9-'Control de lotes'!L9)/D9))) | J9: =IF(A9="","",'Control de lotes'!N9) | K9: =IF(A9="","",IF(NOT(ISNUMBER('Control de lotes'!N9)),"falta dato",IF('Control de lotes'!M9<=0,"falta dato",'Control de lotes'!N9/'Control de lotes'!M9))) | N9: % de margen de contribución | O9: =IF(NOT(ISNUMBER(O8)),"falta dato",IF(O6<=0,"falta dato",O8/O6))
A10: =IF('Control de lotes'!A10="","",'Control de lotes'!A10) | B10: =IF(A10="","",IF(OR('Control de lotes'!D10="",'Control de lotes'!D10=0),"falta dato",IF('Control de lotes'!E10="",0,'Control de lotes'!E10)/'Control de lotes'!D10)) | C10: =IF(A10="","",IF(OR(NOT(ISNUMBER('Control de lotes'!H10)),'Control de lotes'!J10=0),"falta dato",IF('Control de lotes'!H10<=0,"falta dato",'Control de lotes'!J10/'Control de lotes'!H10))) | D10: =IF(A10="","",IF(OR('Control de lotes'!J10=0,'Control de lotes'!D10="",'Control de lotes'!F10=""),"falta dato",'Control de lotes'!J10-'Control de lotes'!D10*'Control de lotes'!F10)) | E10: =IF(A10="","",IF(OR('Control de lotes'!G10="",NOT(ISNUMBER(D10))),"falta dato",IF(D10<=0,"falta dato",'Control de lotes'!G10/D10))) | F10: =IF(A10="","",IF(OR(NOT(ISNUMBER(C10)),'Control de lotes'!F10="",NOT(ISNUMBER('Control de lotes'!I10))),"falta dato",IF('Control de lotes'!I10<=0,"falta dato",(C10-'Control de lotes'!F10)/'Control de lotes'!I10))) | G10: =IF(A10="","",IF(OR(NOT(ISNUMBER('Control de lotes'!H10)),'Control de lotes'!K10=0),"falta dato",IF('Control de lotes'!H10<=0,"falta dato",'Control de lotes'!K10/'Control de lotes'!H10))) | H10: =IF(A10="","",IF(OR('Control de lotes'!J10=0,'Control de lotes'!K10=0),"falta dato",'Control de lotes'!K10/'Control de lotes'!J10)) | I10: =IF(A10="","",IF(OR(NOT(ISNUMBER(D10)),'Control de lotes'!K10=0),"falta dato",IF(D10<=0,"falta dato",('Control de lotes'!K10-'Control de lotes'!L10)/D10))) | J10: =IF(A10="","",'Control de lotes'!N10) | K10: =IF(A10="","",IF(NOT(ISNUMBER('Control de lotes'!N10)),"falta dato",IF('Control de lotes'!M10<=0,"falta dato",'Control de lotes'!N10/'Control de lotes'!M10))) | N10: Punto de equilibrio (cerdos al mes) | O10: =IF(OR(O5="",NOT(ISNUMBER(O8))),"falta dato",IF(O8<=0,"no existe: el precio no cubre el costo variable",O5/O8))
A11: =IF('Control de lotes'!A11="","",'Control de lotes'!A11) | B11: =IF(A11="","",IF(OR('Control de lotes'!D11="",'Control de lotes'!D11=0),"falta dato",IF('Control de lotes'!E11="",0,'Control de lotes'!E11)/'Control de lotes'!D11)) | C11: =IF(A11="","",IF(OR(NOT(ISNUMBER('Control de lotes'!H11)),'Control de lotes'!J11=0),"falta dato",IF('Control de lotes'!H11<=0,"falta dato",'Control de lotes'!J11/'Control de lotes'!H11))) | D11: =IF(A11="","",IF(OR('Control de lotes'!J11=0,'Control de lotes'!D11="",'Control de lotes'!F11=""),"falta dato",'Control de lotes'!J11-'Control de lotes'!D11*'Control de lotes'!F11)) | E11: =IF(A11="","",IF(OR('Control de lotes'!G11="",NOT(ISNUMBER(D11))),"falta dato",IF(D11<=0,"falta dato",'Control de lotes'!G11/D11))) | F11: =IF(A11="","",IF(OR(NOT(ISNUMBER(C11)),'Control de lotes'!F11="",NOT(ISNUMBER('Control de lotes'!I11))),"falta dato",IF('Control de lotes'!I11<=0,"falta dato",(C11-'Control de lotes'!F11)/'Control de lotes'!I11))) | G11: =IF(A11="","",IF(OR(NOT(ISNUMBER('Control de lotes'!H11)),'Control de lotes'!K11=0),"falta dato",IF('Control de lotes'!H11<=0,"falta dato",'Control de lotes'!K11/'Control de lotes'!H11))) | H11: =IF(A11="","",IF(OR('Control de lotes'!J11=0,'Control de lotes'!K11=0),"falta dato",'Control de lotes'!K11/'Control de lotes'!J11)) | I11: =IF(A11="","",IF(OR(NOT(ISNUMBER(D11)),'Control de lotes'!K11=0),"falta dato",IF(D11<=0,"falta dato",('Control de lotes'!K11-'Control de lotes'!L11)/D11))) | J11: =IF(A11="","",'Control de lotes'!N11) | K11: =IF(A11="","",IF(NOT(ISNUMBER('Control de lotes'!N11)),"falta dato",IF('Control de lotes'!M11<=0,"falta dato",'Control de lotes'!N11/'Control de lotes'!M11))) | N11: En la práctica (redondeado hacia arriba) | O11: =IF(ISNUMBER(O10),ROUNDUP(O10,0),O10)
A12: =IF('Control de lotes'!A12="","",'Control de lotes'!A12) | B12: =IF(A12="","",IF(OR('Control de lotes'!D12="",'Control de lotes'!D12=0),"falta dato",IF('Control de lotes'!E12="",0,'Control de lotes'!E12)/'Control de lotes'!D12)) | C12: =IF(A12="","",IF(OR(NOT(ISNUMBER('Control de lotes'!H12)),'Control de lotes'!J12=0),"falta dato",IF('Control de lotes'!H12<=0,"falta dato",'Control de lotes'!J12/'Control de lotes'!H12))) | D12: =IF(A12="","",IF(OR('Control de lotes'!J12=0,'Control de lotes'!D12="",'Control de lotes'!F12=""),"falta dato",'Control de lotes'!J12-'Control de lotes'!D12*'Control de lotes'!F12)) | E12: =IF(A12="","",IF(OR('Control de lotes'!G12="",NOT(ISNUMBER(D12))),"falta dato",IF(D12<=0,"falta dato",'Control de lotes'!G12/D12))) | F12: =IF(A12="","",IF(OR(NOT(ISNUMBER(C12)),'Control de lotes'!F12="",NOT(ISNUMBER('Control de lotes'!I12))),"falta dato",IF('Control de lotes'!I12<=0,"falta dato",(C12-'Control de lotes'!F12)/'Control de lotes'!I12))) | G12: =IF(A12="","",IF(OR(NOT(ISNUMBER('Control de lotes'!H12)),'Control de lotes'!K12=0),"falta dato",IF('Control de lotes'!H12<=0,"falta dato",'Control de lotes'!K12/'Control de lotes'!H12))) | H12: =IF(A12="","",IF(OR('Control de lotes'!J12=0,'Control de lotes'!K12=0),"falta dato",'Control de lotes'!K12/'Control de lotes'!J12)) | I12: =IF(A12="","",IF(OR(NOT(ISNUMBER(D12)),'Control de lotes'!K12=0),"falta dato",IF(D12<=0,"falta dato",('Control de lotes'!K12-'Control de lotes'!L12)/D12))) | J12: =IF(A12="","",'Control de lotes'!N12) | K12: =IF(A12="","",IF(NOT(ISNUMBER('Control de lotes'!N12)),"falta dato",IF('Control de lotes'!M12<=0,"falta dato",'Control de lotes'!N12/'Control de lotes'!M12))) | N12: Punto de equilibrio en ventas | O12: =IF(ISNUMBER(O10),O10*O6,O10)
A13: =IF('Control de lotes'!A13="","",'Control de lotes'!A13) | B13: =IF(A13="","",IF(OR('Control de lotes'!D13="",'Control de lotes'!D13=0),"falta dato",IF('Control de lotes'!E13="",0,'Control de lotes'!E13)/'Control de lotes'!D13)) | C13: =IF(A13="","",IF(OR(NOT(ISNUMBER('Control de lotes'!H13)),'Control de lotes'!J13=0),"falta dato",IF('Control de lotes'!H13<=0,"falta dato",'Control de lotes'!J13/'Control de lotes'!H13))) | D13: =IF(A13="","",IF(OR('Control de lotes'!J13=0,'Control de lotes'!D13="",'Control de lotes'!F13=""),"falta dato",'Control de lotes'!J13-'Control de lotes'!D13*'Control de lotes'!F13)) | E13: =IF(A13="","",IF(OR('Control de lotes'!G13="",NOT(ISNUMBER(D13))),"falta dato",IF(D13<=0,"falta dato",'Control de lotes'!G13/D13))) | F13: =IF(A13="","",IF(OR(NOT(ISNUMBER(C13)),'Control de lotes'!F13="",NOT(ISNUMBER('Control de lotes'!I13))),"falta dato",IF('Control de lotes'!I13<=0,"falta dato",(C13-'Control de lotes'!F13)/'Control de lotes'!I13))) | G13: =IF(A13="","",IF(OR(NOT(ISNUMBER('Control de lotes'!H13)),'Control de lotes'!K13=0),"falta dato",IF('Control de lotes'!H13<=0,"falta dato",'Control de lotes'!K13/'Control de lotes'!H13))) | H13: =IF(A13="","",IF(OR('Control de lotes'!J13=0,'Control de lotes'!K13=0),"falta dato",'Control de lotes'!K13/'Control de lotes'!J13)) | I13: =IF(A13="","",IF(OR(NOT(ISNUMBER(D13)),'Control de lotes'!K13=0),"falta dato",IF(D13<=0,"falta dato",('Control de lotes'!K13-'Control de lotes'!L13)/D13))) | J13: =IF(A13="","",'Control de lotes'!N13) | K13: =IF(A13="","",IF(NOT(ISNUMBER('Control de lotes'!N13)),"falta dato",IF('Control de lotes'!M13<=0,"falta dato",'Control de lotes'!N13/'Control de lotes'!M13)))
A14: =IF('Control de lotes'!A14="","",'Control de lotes'!A14) | B14: =IF(A14="","",IF(OR('Control de lotes'!D14="",'Control de lotes'!D14=0),"falta dato",IF('Control de lotes'!E14="",0,'Control de lotes'!E14)/'Control de lotes'!D14)) | C14: =IF(A14="","",IF(OR(NOT(ISNUMBER('Control de lotes'!H14)),'Control de lotes'!J14=0),"falta dato",IF('Control de lotes'!H14<=0,"falta dato",'Control de lotes'!J14/'Control de lotes'!H14))) | D14: =IF(A14="","",IF(OR('Control de lotes'!J14=0,'Control de lotes'!D14="",'Control de lotes'!F14=""),"falta dato",'Control de lotes'!J14-'Control de lotes'!D14*'Control de lotes'!F14)) | E14: =IF(A14="","",IF(OR('Control de lotes'!G14="",NOT(ISNUMBER(D14))),"falta dato",IF(D14<=0,"falta dato",'Control de lotes'!G14/D14))) | F14: =IF(A14="","",IF(OR(NOT(ISNUMBER(C14)),'Control de lotes'!F14="",NOT(ISNUMBER('Control de lotes'!I14))),"falta dato",IF('Control de lotes'!I14<=0,"falta dato",(C14-'Control de lotes'!F14)/'Control de lotes'!I14))) | G14: =IF(A14="","",IF(OR(NOT(ISNUMBER('Control de lotes'!H14)),'Control de lotes'!K14=0),"falta dato",IF('Control de lotes'!H14<=0,"falta dato",'Control de lotes'!K14/'Control de lotes'!H14))) | H14: =IF(A14="","",IF(OR('Control de lotes'!J14=0,'Control de lotes'!K14=0),"falta dato",'Control de lotes'!K14/'Control de lotes'!J14)) | I14: =IF(A14="","",IF(OR(NOT(ISNUMBER(D14)),'Control de lotes'!K14=0),"falta dato",IF(D14<=0,"falta dato",('Control de lotes'!K14-'Control de lotes'!L14)/D14))) | J14: =IF(A14="","",'Control de lotes'!N14) | K14: =IF(A14="","",IF(NOT(ISNUMBER('Control de lotes'!N14)),"falta dato",IF('Control de lotes'!M14<=0,"falta dato",'Control de lotes'!N14/'Control de lotes'!M14))) | N14: Los tres valores amarillos son de EJEMPLO (módulo 6 del curso). Escriba los de su granja.
A15: =IF('Control de lotes'!A15="","",'Control de lotes'!A15) | B15: =IF(A15="","",IF(OR('Control de lotes'!D15="",'Control de lotes'!D15=0),"falta dato",IF('Control de lotes'!E15="",0,'Control de lotes'!E15)/'Control de lotes'!D15)) | C15: =IF(A15="","",IF(OR(NOT(ISNUMBER('Control de lotes'!H15)),'Control de lotes'!J15=0),"falta dato",IF('Control de lotes'!H15<=0,"falta dato",'Control de lotes'!J15/'Control de lotes'!H15))) | D15: =IF(A15="","",IF(OR('Control de lotes'!J15=0,'Control de lotes'!D15="",'Control de lotes'!F15=""),"falta dato",'Control de lotes'!J15-'Control de lotes'!D15*'Control de lotes'!F15)) | E15: =IF(A15="","",IF(OR('Control de lotes'!G15="",NOT(ISNUMBER(D15))),"falta dato",IF(D15<=0,"falta dato",'Control de lotes'!G15/D15))) | F15: =IF(A15="","",IF(OR(NOT(ISNUMBER(C15)),'Control de lotes'!F15="",NOT(ISNUMBER('Control de lotes'!I15))),"falta dato",IF('Control de lotes'!I15<=0,"falta dato",(C15-'Control de lotes'!F15)/'Control de lotes'!I15))) | G15: =IF(A15="","",IF(OR(NOT(ISNUMBER('Control de lotes'!H15)),'Control de lotes'!K15=0),"falta dato",IF('Control de lotes'!H15<=0,"falta dato",'Control de lotes'!K15/'Control de lotes'!H15))) | H15: =IF(A15="","",IF(OR('Control de lotes'!J15=0,'Control de lotes'!K15=0),"falta dato",'Control de lotes'!K15/'Control de lotes'!J15)) | I15: =IF(A15="","",IF(OR(NOT(ISNUMBER(D15)),'Control de lotes'!K15=0),"falta dato",IF(D15<=0,"falta dato",('Control de lotes'!K15-'Control de lotes'!L15)/D15))) | J15: =IF(A15="","",'Control de lotes'!N15) | K15: =IF(A15="","",IF(NOT(ISNUMBER('Control de lotes'!N15)),"falta dato",IF('Control de lotes'!M15<=0,"falta dato",'Control de lotes'!N15/'Control de lotes'!M15)))
A16: =IF('Control de lotes'!A16="","",'Control de lotes'!A16) | B16: =IF(A16="","",IF(OR('Control de lotes'!D16="",'Control de lotes'!D16=0),"falta dato",IF('Control de lotes'!E16="",0,'Control de lotes'!E16)/'Control de lotes'!D16)) | C16: =IF(A16="","",IF(OR(NOT(ISNUMBER('Control de lotes'!H16)),'Control de lotes'!J16=0),"falta dato",IF('Control de lotes'!H16<=0,"falta dato",'Control de lotes'!J16/'Control de lotes'!H16))) | D16: =IF(A16="","",IF(OR('Control de lotes'!J16=0,'Control de lotes'!D16="",'Control de lotes'!F16=""),"falta dato",'Control de lotes'!J16-'Control de lotes'!D16*'Control de lotes'!F16)) | E16: =IF(A16="","",IF(OR('Control de lotes'!G16="",NOT(ISNUMBER(D16))),"falta dato",IF(D16<=0,"falta dato",'Control de lotes'!G16/D16))) | F16: =IF(A16="","",IF(OR(NOT(ISNUMBER(C16)),'Control de lotes'!F16="",NOT(ISNUMBER('Control de lotes'!I16))),"falta dato",IF('Control de lotes'!I16<=0,"falta dato",(C16-'Control de lotes'!F16)/'Control de lotes'!I16))) | G16: =IF(A16="","",IF(OR(NOT(ISNUMBER('Control de lotes'!H16)),'Control de lotes'!K16=0),"falta dato",IF('Control de lotes'!H16<=0,"falta dato",'Control de lotes'!K16/'Control de lotes'!H16))) | H16: =IF(A16="","",IF(OR('Control de lotes'!J16=0,'Control de lotes'!K16=0),"falta dato",'Control de lotes'!K16/'Control de lotes'!J16)) | I16: =IF(A16="","",IF(OR(NOT(ISNUMBER(D16)),'Control de lotes'!K16=0),"falta dato",IF(D16<=0,"falta dato",('Control de lotes'!K16-'Control de lotes'!L16)/D16))) | J16: =IF(A16="","",'Control de lotes'!N16) | K16: =IF(A16="","",IF(NOT(ISNUMBER('Control de lotes'!N16)),"falta dato",IF('Control de lotes'!M16<=0,"falta dato",'Control de lotes'!N16/'Control de lotes'!M16)))
A17: =IF('Control de lotes'!A17="","",'Control de lotes'!A17) | B17: =IF(A17="","",IF(OR('Control de lotes'!D17="",'Control de lotes'!D17=0),"falta dato",IF('Control de lotes'!E17="",0,'Control de lotes'!E17)/'Control de lotes'!D17)) | C17: =IF(A17="","",IF(OR(NOT(ISNUMBER('Control de lotes'!H17)),'Control de lotes'!J17=0),"falta dato",IF('Control de lotes'!H17<=0,"falta dato",'Control de lotes'!J17/'Control de lotes'!H17))) | D17: =IF(A17="","",IF(OR('Control de lotes'!J17=0,'Control de lotes'!D17="",'Control de lotes'!F17=""),"falta dato",'Control de lotes'!J17-'Control de lotes'!D17*'Control de lotes'!F17)) | E17: =IF(A17="","",IF(OR('Control de lotes'!G17="",NOT(ISNUMBER(D17))),"falta dato",IF(D17<=0,"falta dato",'Control de lotes'!G17/D17))) | F17: =IF(A17="","",IF(OR(NOT(ISNUMBER(C17)),'Control de lotes'!F17="",NOT(ISNUMBER('Control de lotes'!I17))),"falta dato",IF('Control de lotes'!I17<=0,"falta dato",(C17-'Control de lotes'!F17)/'Control de lotes'!I17))) | G17: =IF(A17="","",IF(OR(NOT(ISNUMBER('Control de lotes'!H17)),'Control de lotes'!K17=0),"falta dato",IF('Control de lotes'!H17<=0,"falta dato",'Control de lotes'!K17/'Control de lotes'!H17))) | H17: =IF(A17="","",IF(OR('Control de lotes'!J17=0,'Control de lotes'!K17=0),"falta dato",'Control de lotes'!K17/'Control de lotes'!J17)) | I17: =IF(A17="","",IF(OR(NOT(ISNUMBER(D17)),'Control de lotes'!K17=0),"falta dato",IF(D17<=0,"falta dato",('Control de lotes'!K17-'Control de lotes'!L17)/D17))) | J17: =IF(A17="","",'Control de lotes'!N17) | K17: =IF(A17="","",IF(NOT(ISNUMBER('Control de lotes'!N17)),"falta dato",IF('Control de lotes'!M17<=0,"falta dato",'Control de lotes'!N17/'Control de lotes'!M17)))
A18: =IF('Control de lotes'!A18="","",'Control de lotes'!A18) | B18: =IF(A18="","",IF(OR('Control de lotes'!D18="",'Control de lotes'!D18=0),"falta dato",IF('Control de lotes'!E18="",0,'Control de lotes'!E18)/'Control de lotes'!D18)) | C18: =IF(A18="","",IF(OR(NOT(ISNUMBER('Control de lotes'!H18)),'Control de lotes'!J18=0),"falta dato",IF('Control de lotes'!H18<=0,"falta dato",'Control de lotes'!J18/'Control de lotes'!H18))) | D18: =IF(A18="","",IF(OR('Control de lotes'!J18=0,'Control de lotes'!D18="",'Control de lotes'!F18=""),"falta dato",'Control de lotes'!J18-'Control de lotes'!D18*'Control de lotes'!F18)) | E18: =IF(A18="","",IF(OR('Control de lotes'!G18="",NOT(ISNUMBER(D18))),"falta dato",IF(D18<=0,"falta dato",'Control de lotes'!G18/D18))) | F18: =IF(A18="","",IF(OR(NOT(ISNUMBER(C18)),'Control de lotes'!F18="",NOT(ISNUMBER('Control de lotes'!I18))),"falta dato",IF('Control de lotes'!I18<=0,"falta dato",(C18-'Control de lotes'!F18)/'Control de lotes'!I18))) | G18: =IF(A18="","",IF(OR(NOT(ISNUMBER('Control de lotes'!H18)),'Control de lotes'!K18=0),"falta dato",IF('Control de lotes'!H18<=0,"falta dato",'Control de lotes'!K18/'Control de lotes'!H18))) | H18: =IF(A18="","",IF(OR('Control de lotes'!J18=0,'Control de lotes'!K18=0),"falta dato",'Control de lotes'!K18/'Control de lotes'!J18)) | I18: =IF(A18="","",IF(OR(NOT(ISNUMBER(D18)),'Control de lotes'!K18=0),"falta dato",IF(D18<=0,"falta dato",('Control de lotes'!K18-'Control de lotes'!L18)/D18))) | J18: =IF(A18="","",'Control de lotes'!N18) | K18: =IF(A18="","",IF(NOT(ISNUMBER('Control de lotes'!N18)),"falta dato",IF('Control de lotes'!M18<=0,"falta dato",'Control de lotes'!N18/'Control de lotes'!M18)))
A19: =IF('Control de lotes'!A19="","",'Control de lotes'!A19) | B19: =IF(A19="","",IF(OR('Control de lotes'!D19="",'Control de lotes'!D19=0),"falta dato",IF('Control de lotes'!E19="",0,'Control de lotes'!E19)/'Control de lotes'!D19)) | C19: =IF(A19="","",IF(OR(NOT(ISNUMBER('Control de lotes'!H19)),'Control de lotes'!J19=0),"falta dato",IF('Control de lotes'!H19<=0,"falta dato",'Control de lotes'!J19/'Control de lotes'!H19))) | D19: =IF(A19="","",IF(OR('Control de lotes'!J19=0,'Control de lotes'!D19="",'Control de lotes'!F19=""),"falta dato",'Control de lotes'!J19-'Control de lotes'!D19*'Control de lotes'!F19)) | E19: =IF(A19="","",IF(OR('Control de lotes'!G19="",NOT(ISNUMBER(D19))),"falta dato",IF(D19<=0,"falta dato",'Control de lotes'!G19/D19))) | F19: =IF(A19="","",IF(OR(NOT(ISNUMBER(C19)),'Control de lotes'!F19="",NOT(ISNUMBER('Control de lotes'!I19))),"falta dato",IF('Control de lotes'!I19<=0,"falta dato",(C19-'Control de lotes'!F19)/'Control de lotes'!I19))) | G19: =IF(A19="","",IF(OR(NOT(ISNUMBER('Control de lotes'!H19)),'Control de lotes'!K19=0),"falta dato",IF('Control de lotes'!H19<=0,"falta dato",'Control de lotes'!K19/'Control de lotes'!H19))) | H19: =IF(A19="","",IF(OR('Control de lotes'!J19=0,'Control de lotes'!K19=0),"falta dato",'Control de lotes'!K19/'Control de lotes'!J19)) | I19: =IF(A19="","",IF(OR(NOT(ISNUMBER(D19)),'Control de lotes'!K19=0),"falta dato",IF(D19<=0,"falta dato",('Control de lotes'!K19-'Control de lotes'!L19)/D19))) | J19: =IF(A19="","",'Control de lotes'!N19) | K19: =IF(A19="","",IF(NOT(ISNUMBER('Control de lotes'!N19)),"falta dato",IF('Control de lotes'!M19<=0,"falta dato",'Control de lotes'!N19/'Control de lotes'!M19)))
A20: =IF('Control de lotes'!A20="","",'Control de lotes'!A20) | B20: =IF(A20="","",IF(OR('Control de lotes'!D20="",'Control de lotes'!D20=0),"falta dato",IF('Control de lotes'!E20="",0,'Control de lotes'!E20)/'Control de lotes'!D20)) | C20: =IF(A20="","",IF(OR(NOT(ISNUMBER('Control de lotes'!H20)),'Control de lotes'!J20=0),"falta dato",IF('Control de lotes'!H20<=0,"falta dato",'Control de lotes'!J20/'Control de lotes'!H20))) | D20: =IF(A20="","",IF(OR('Control de lotes'!J20=0,'Control de lotes'!D20="",'Control de lotes'!F20=""),"falta dato",'Control de lotes'!J20-'Control de lotes'!D20*'Control de lotes'!F20)) | E20: =IF(A20="","",IF(OR('Control de lotes'!G20="",NOT(ISNUMBER(D20))),"falta dato",IF(D20<=0,"falta dato",'Control de lotes'!G20/D20))) | F20: =IF(A20="","",IF(OR(NOT(ISNUMBER(C20)),'Control de lotes'!F20="",NOT(ISNUMBER('Control de lotes'!I20))),"falta dato",IF('Control de lotes'!I20<=0,"falta dato",(C20-'Control de lotes'!F20)/'Control de lotes'!I20))) | G20: =IF(A20="","",IF(OR(NOT(ISNUMBER('Control de lotes'!H20)),'Control de lotes'!K20=0),"falta dato",IF('Control de lotes'!H20<=0,"falta dato",'Control de lotes'!K20/'Control de lotes'!H20))) | H20: =IF(A20="","",IF(OR('Control de lotes'!J20=0,'Control de lotes'!K20=0),"falta dato",'Control de lotes'!K20/'Control de lotes'!J20)) | I20: =IF(A20="","",IF(OR(NOT(ISNUMBER(D20)),'Control de lotes'!K20=0),"falta dato",IF(D20<=0,"falta dato",('Control de lotes'!K20-'Control de lotes'!L20)/D20))) | J20: =IF(A20="","",'Control de lotes'!N20) | K20: =IF(A20="","",IF(NOT(ISNUMBER('Control de lotes'!N20)),"falta dato",IF('Control de lotes'!M20<=0,"falta dato",'Control de lotes'!N20/'Control de lotes'!M20)))
A21: =IF('Control de lotes'!A21="","",'Control de lotes'!A21) | B21: =IF(A21="","",IF(OR('Control de lotes'!D21="",'Control de lotes'!D21=0),"falta dato",IF('Control de lotes'!E21="",0,'Control de lotes'!E21)/'Control de lotes'!D21)) | C21: =IF(A21="","",IF(OR(NOT(ISNUMBER('Control de lotes'!H21)),'Control de lotes'!J21=0),"falta dato",IF('Control de lotes'!H21<=0,"falta dato",'Control de lotes'!J21/'Control de lotes'!H21))) | D21: =IF(A21="","",IF(OR('Control de lotes'!J21=0,'Control de lotes'!D21="",'Control de lotes'!F21=""),"falta dato",'Control de lotes'!J21-'Control de lotes'!D21*'Control de lotes'!F21)) | E21: =IF(A21="","",IF(OR('Control de lotes'!G21="",NOT(ISNUMBER(D21))),"falta dato",IF(D21<=0,"falta dato",'Control de lotes'!G21/D21))) | F21: =IF(A21="","",IF(OR(NOT(ISNUMBER(C21)),'Control de lotes'!F21="",NOT(ISNUMBER('Control de lotes'!I21))),"falta dato",IF('Control de lotes'!I21<=0,"falta dato",(C21-'Control de lotes'!F21)/'Control de lotes'!I21))) | G21: =IF(A21="","",IF(OR(NOT(ISNUMBER('Control de lotes'!H21)),'Control de lotes'!K21=0),"falta dato",IF('Control de lotes'!H21<=0,"falta dato",'Control de lotes'!K21/'Control de lotes'!H21))) | H21: =IF(A21="","",IF(OR('Control de lotes'!J21=0,'Control de lotes'!K21=0),"falta dato",'Control de lotes'!K21/'Control de lotes'!J21)) | I21: =IF(A21="","",IF(OR(NOT(ISNUMBER(D21)),'Control de lotes'!K21=0),"falta dato",IF(D21<=0,"falta dato",('Control de lotes'!K21-'Control de lotes'!L21)/D21))) | J21: =IF(A21="","",'Control de lotes'!N21) | K21: =IF(A21="","",IF(NOT(ISNUMBER('Control de lotes'!N21)),"falta dato",IF('Control de lotes'!M21<=0,"falta dato",'Control de lotes'!N21/'Control de lotes'!M21)))
A22: =IF('Control de lotes'!A22="","",'Control de lotes'!A22) | B22: =IF(A22="","",IF(OR('Control de lotes'!D22="",'Control de lotes'!D22=0),"falta dato",IF('Control de lotes'!E22="",0,'Control de lotes'!E22)/'Control de lotes'!D22)) | C22: =IF(A22="","",IF(OR(NOT(ISNUMBER('Control de lotes'!H22)),'Control de lotes'!J22=0),"falta dato",IF('Control de lotes'!H22<=0,"falta dato",'Control de lotes'!J22/'Control de lotes'!H22))) | D22: =IF(A22="","",IF(OR('Control de lotes'!J22=0,'Control de lotes'!D22="",'Control de lotes'!F22=""),"falta dato",'Control de lotes'!J22-'Control de lotes'!D22*'Control de lotes'!F22)) | E22: =IF(A22="","",IF(OR('Control de lotes'!G22="",NOT(ISNUMBER(D22))),"falta dato",IF(D22<=0,"falta dato",'Control de lotes'!G22/D22))) | F22: =IF(A22="","",IF(OR(NOT(ISNUMBER(C22)),'Control de lotes'!F22="",NOT(ISNUMBER('Control de lotes'!I22))),"falta dato",IF('Control de lotes'!I22<=0,"falta dato",(C22-'Control de lotes'!F22)/'Control de lotes'!I22))) | G22: =IF(A22="","",IF(OR(NOT(ISNUMBER('Control de lotes'!H22)),'Control de lotes'!K22=0),"falta dato",IF('Control de lotes'!H22<=0,"falta dato",'Control de lotes'!K22/'Control de lotes'!H22))) | H22: =IF(A22="","",IF(OR('Control de lotes'!J22=0,'Control de lotes'!K22=0),"falta dato",'Control de lotes'!K22/'Control de lotes'!J22)) | I22: =IF(A22="","",IF(OR(NOT(ISNUMBER(D22)),'Control de lotes'!K22=0),"falta dato",IF(D22<=0,"falta dato",('Control de lotes'!K22-'Control de lotes'!L22)/D22))) | J22: =IF(A22="","",'Control de lotes'!N22) | K22: =IF(A22="","",IF(NOT(ISNUMBER('Control de lotes'!N22)),"falta dato",IF('Control de lotes'!M22<=0,"falta dato",'Control de lotes'!N22/'Control de lotes'!M22)))
A23: =IF('Control de lotes'!A23="","",'Control de lotes'!A23) | B23: =IF(A23="","",IF(OR('Control de lotes'!D23="",'Control de lotes'!D23=0),"falta dato",IF('Control de lotes'!E23="",0,'Control de lotes'!E23)/'Control de lotes'!D23)) | C23: =IF(A23="","",IF(OR(NOT(ISNUMBER('Control de lotes'!H23)),'Control de lotes'!J23=0),"falta dato",IF('Control de lotes'!H23<=0,"falta dato",'Control de lotes'!J23/'Control de lotes'!H23))) | D23: =IF(A23="","",IF(OR('Control de lotes'!J23=0,'Control de lotes'!D23="",'Control de lotes'!F23=""),"falta dato",'Control de lotes'!J23-'Control de lotes'!D23*'Control de lotes'!F23)) | E23: =IF(A23="","",IF(OR('Control de lotes'!G23="",NOT(ISNUMBER(D23))),"falta dato",IF(D23<=0,"falta dato",'Control de lotes'!G23/D23))) | F23: =IF(A23="","",IF(OR(NOT(ISNUMBER(C23)),'Control de lotes'!F23="",NOT(ISNUMBER('Control de lotes'!I23))),"falta dato",IF('Control de lotes'!I23<=0,"falta dato",(C23-'Control de lotes'!F23)/'Control de lotes'!I23))) | G23: =IF(A23="","",IF(OR(NOT(ISNUMBER('Control de lotes'!H23)),'Control de lotes'!K23=0),"falta dato",IF('Control de lotes'!H23<=0,"falta dato",'Control de lotes'!K23/'Control de lotes'!H23))) | H23: =IF(A23="","",IF(OR('Control de lotes'!J23=0,'Control de lotes'!K23=0),"falta dato",'Control de lotes'!K23/'Control de lotes'!J23)) | I23: =IF(A23="","",IF(OR(NOT(ISNUMBER(D23)),'Control de lotes'!K23=0),"falta dato",IF(D23<=0,"falta dato",('Control de lotes'!K23-'Control de lotes'!L23)/D23))) | J23: =IF(A23="","",'Control de lotes'!N23) | K23: =IF(A23="","",IF(NOT(ISNUMBER('Control de lotes'!N23)),"falta dato",IF('Control de lotes'!M23<=0,"falta dato",'Control de lotes'!N23/'Control de lotes'!M23)))
A24: =IF('Control de lotes'!A24="","",'Control de lotes'!A24) | B24: =IF(A24="","",IF(OR('Control de lotes'!D24="",'Control de lotes'!D24=0),"falta dato",IF('Control de lotes'!E24="",0,'Control de lotes'!E24)/'Control de lotes'!D24)) | C24: =IF(A24="","",IF(OR(NOT(ISNUMBER('Control de lotes'!H24)),'Control de lotes'!J24=0),"falta dato",IF('Control de lotes'!H24<=0,"falta dato",'Control de lotes'!J24/'Control de lotes'!H24))) | D24: =IF(A24="","",IF(OR('Control de lotes'!J24=0,'Control de lotes'!D24="",'Control de lotes'!F24=""),"falta dato",'Control de lotes'!J24-'Control de lotes'!D24*'Control de lotes'!F24)) | E24: =IF(A24="","",IF(OR('Control de lotes'!G24="",NOT(ISNUMBER(D24))),"falta dato",IF(D24<=0,"falta dato",'Control de lotes'!G24/D24))) | F24: =IF(A24="","",IF(OR(NOT(ISNUMBER(C24)),'Control de lotes'!F24="",NOT(ISNUMBER('Control de lotes'!I24))),"falta dato",IF('Control de lotes'!I24<=0,"falta dato",(C24-'Control de lotes'!F24)/'Control de lotes'!I24))) | G24: =IF(A24="","",IF(OR(NOT(ISNUMBER('Control de lotes'!H24)),'Control de lotes'!K24=0),"falta dato",IF('Control de lotes'!H24<=0,"falta dato",'Control de lotes'!K24/'Control de lotes'!H24))) | H24: =IF(A24="","",IF(OR('Control de lotes'!J24=0,'Control de lotes'!K24=0),"falta dato",'Control de lotes'!K24/'Control de lotes'!J24)) | I24: =IF(A24="","",IF(OR(NOT(ISNUMBER(D24)),'Control de lotes'!K24=0),"falta dato",IF(D24<=0,"falta dato",('Control de lotes'!K24-'Control de lotes'!L24)/D24))) | J24: =IF(A24="","",'Control de lotes'!N24) | K24: =IF(A24="","",IF(NOT(ISNUMBER('Control de lotes'!N24)),"falta dato",IF('Control de lotes'!M24<=0,"falta dato",'Control de lotes'!N24/'Control de lotes'!M24)))
A25: =IF('Control de lotes'!A25="","",'Control de lotes'!A25) | B25: =IF(A25="","",IF(OR('Control de lotes'!D25="",'Control de lotes'!D25=0),"falta dato",IF('Control de lotes'!E25="",0,'Control de lotes'!E25)/'Control de lotes'!D25)) | C25: =IF(A25="","",IF(OR(NOT(ISNUMBER('Control de lotes'!H25)),'Control de lotes'!J25=0),"falta dato",IF('Control de lotes'!H25<=0,"falta dato",'Control de lotes'!J25/'Control de lotes'!H25))) | D25: =IF(A25="","",IF(OR('Control de lotes'!J25=0,'Control de lotes'!D25="",'Control de lotes'!F25=""),"falta dato",'Control de lotes'!J25-'Control de lotes'!D25*'Control de lotes'!F25)) | E25: =IF(A25="","",IF(OR('Control de lotes'!G25="",NOT(ISNUMBER(D25))),"falta dato",IF(D25<=0,"falta dato",'Control de lotes'!G25/D25))) | F25: =IF(A25="","",IF(OR(NOT(ISNUMBER(C25)),'Control de lotes'!F25="",NOT(ISNUMBER('Control de lotes'!I25))),"falta dato",IF('Control de lotes'!I25<=0,"falta dato",(C25-'Control de lotes'!F25)/'Control de lotes'!I25))) | G25: =IF(A25="","",IF(OR(NOT(ISNUMBER('Control de lotes'!H25)),'Control de lotes'!K25=0),"falta dato",IF('Control de lotes'!H25<=0,"falta dato",'Control de lotes'!K25/'Control de lotes'!H25))) | H25: =IF(A25="","",IF(OR('Control de lotes'!J25=0,'Control de lotes'!K25=0),"falta dato",'Control de lotes'!K25/'Control de lotes'!J25)) | I25: =IF(A25="","",IF(OR(NOT(ISNUMBER(D25)),'Control de lotes'!K25=0),"falta dato",IF(D25<=0,"falta dato",('Control de lotes'!K25-'Control de lotes'!L25)/D25))) | J25: =IF(A25="","",'Control de lotes'!N25) | K25: =IF(A25="","",IF(NOT(ISNUMBER('Control de lotes'!N25)),"falta dato",IF('Control de lotes'!M25<=0,"falta dato",'Control de lotes'!N25/'Control de lotes'!M25)))
A26: =IF('Control de lotes'!A26="","",'Control de lotes'!A26) | B26: =IF(A26="","",IF(OR('Control de lotes'!D26="",'Control de lotes'!D26=0),"falta dato",IF('Control de lotes'!E26="",0,'Control de lotes'!E26)/'Control de lotes'!D26)) | C26: =IF(A26="","",IF(OR(NOT(ISNUMBER('Control de lotes'!H26)),'Control de lotes'!J26=0),"falta dato",IF('Control de lotes'!H26<=0,"falta dato",'Control de lotes'!J26/'Control de lotes'!H26))) | D26: =IF(A26="","",IF(OR('Control de lotes'!J26=0,'Control de lotes'!D26="",'Control de lotes'!F26=""),"falta dato",'Control de lotes'!J26-'Control de lotes'!D26*'Control de lotes'!F26)) | E26: =IF(A26="","",IF(OR('Control de lotes'!G26="",NOT(ISNUMBER(D26))),"falta dato",IF(D26<=0,"falta dato",'Control de lotes'!G26/D26))) | F26: =IF(A26="","",IF(OR(NOT(ISNUMBER(C26)),'Control de lotes'!F26="",NOT(ISNUMBER('Control de lotes'!I26))),"falta dato",IF('Control de lotes'!I26<=0,"falta dato",(C26-'Control de lotes'!F26)/'Control de lotes'!I26))) | G26: =IF(A26="","",IF(OR(NOT(ISNUMBER('Control de lotes'!H26)),'Control de lotes'!K26=0),"falta dato",IF('Control de lotes'!H26<=0,"falta dato",'Control de lotes'!K26/'Control de lotes'!H26))) | H26: =IF(A26="","",IF(OR('Control de lotes'!J26=0,'Control de lotes'!K26=0),"falta dato",'Control de lotes'!K26/'Control de lotes'!J26)) | I26: =IF(A26="","",IF(OR(NOT(ISNUMBER(D26)),'Control de lotes'!K26=0),"falta dato",IF(D26<=0,"falta dato",('Control de lotes'!K26-'Control de lotes'!L26)/D26))) | J26: =IF(A26="","",'Control de lotes'!N26) | K26: =IF(A26="","",IF(NOT(ISNUMBER('Control de lotes'!N26)),"falta dato",IF('Control de lotes'!M26<=0,"falta dato",'Control de lotes'!N26/'Control de lotes'!M26)))
